Workbook
Name test: Sheet1!$A$1:$H$672
Name test: Sheet2!$A$1:$H$650

Sheet Price List by Category
A1: SEAQUEST SEAFOOD CORPORATION
A2: Tel: 626-968-8188 Fax: 626-968-8811 www.sqseafood.com
A3: Effective Date: March 03, 2026
A5: ▶ OCTOPUS & SQUID
A6: Product Description | B6: Vietnamese | C6: Item # | D6: Unit Price | E6: Packaging | F6: Origin | G6: Method | H6: Weight (lbs) | I6: Pack | J6: Pack Type | K6: Case price
A7: BABY LOLIGO SQUID R/P (30) | B7: MUC ONG NHOI | C7: F0403 | D7: 3.25 | E7: 30 X 14 OZ | F7: CHINA | G7: WILD | H7: 26.25 | I7: VP | J7: Retail | K7: =VLOOKUP(C:C,Sheet2!B:H,7,0) -> 97.5
A8: BABY OCTOPUS DS 16/25 (24) | B8: BACH TUOC 2 DA | C8: F0296 | D8: 3.6 | E8: 12 X 2 LB | F8: VIETNAM | G8: WILD | H8: 24 | I8: VP | J8: Retail | K8: =VLOOKUP(C:C,Sheet2!B:H,7,0) -> 86.4
A9: BABY OCTOPUS DS 5/15 (24) | B9: BACH TUOC 2 DA | C9: F0295 | D9: 3.5 | E9: 12 X 2 LB | F9: VIETNAM | G9: WILD | H9: 24 | I9: VP | J9: Retail | K9: =VLOOKUP(C:C,Sheet2!B:H,7,0) -> 84
A10: BABY OCTOPUS SS 16/25 (12x2) | B10: BACH TUOC 1 DA | C10: F0291 | D10: 3.6 | E10: 12 X 2 LB | F10: VIETNAM | G10: WILD | H10: 24 | I10: VP | J10: Retail | K10: =VLOOKUP(C:C,Sheet2!B:H,7,0) -> 86.4
A11: BABY OCTOPUS SS 5/15 (12x2) | B11: BACH TUOC 1 DA | C11: F0290 | D11: 3.5 | E11: 12 X 2 LB | F11: VIETNAM | G11: WILD | H11: 24 | I11: VP | J11: Retail | K11: =VLOOKUP(C:C,Sheet2!B:H,7,0) -> 84
A12: BONO SQUID IQF (22.05) | B12: MUC ONG CALIFORNIA | C12: F0423 | D12: 3.2 | E12: 1 X 22 LB | F12: USA | G12: WILD | H12: 22 | I12: Bulk | J12: Bulk | K12: =VLOOKUP(C:C,Sheet2!B:H,7,0) -> 70.56
A13: CALAMARI SQUID RINGS (30) | B13: KHOANH MUC | C13: F0416 | D13: 3.2 | E13: 30 X 16 OZ | F13: CHINA | G13: WILD | H13: 30 | I13: VP | J13: Retail | K13: =VLOOKUP(C:C,Sheet2!B:H,7,0) -> 96
A14: CALIFORNIA SQUID W/R (36) | B14: MUC ONG NGUYEN CON | C14: F0421 | D14: 2.7 | E14: 12 X 3 LB | F14: USA | G14: WILD | H14: 36 | I14: Box | J14: Retail | K14: =VLOOKUP(C:C,Sheet2!B:H,7,0) -> 97.2
A15: CLN GIANT CUTTLEFISH 2/4 (22) | B15: MUC NANG LAM SACH | C15: F2282 | D15: 4.2 | E15: 1 X 22 LB | F15: INDIA | G15: WILD | H15: 22 | I15: Bulk | J15: Bulk | K15: =VLOOKUP(C:C,Sheet2!B:H,7,0) -> 92.4
A16: CLN GIANT CUTTLEFISH 4/6 (22) | B16: MUC NANG LAM SACH | C16: F2283 | D16: 4.2 | E16: 1 X 22 LB | F16: INDIA | G16: WILD | H16: 22 | I16: Bulk | J16: Bulk | K16: =VLOOKUP(C:C,Sheet2!B:H,7,0) -> 92.4
A17: CURLED CALAMARI CHUNK (30) | B17: MUC XOAN | C17: F0417 | D17: 2.85 | E17: 30 X 14 OZ | F17: CHINA | G17: WILD | H17: 26.25 | I17: VP | J17: Retail | K17: =VLOOKUP(C:C,Sheet2!B:H,7,0) -> 85.5
A18: LOLIGO ROLL 10/15cm (30) | B18: MUC ONG LOLIGO | C18: F0426 | D18: 8.3 | E18: 30 X 16 OZ | F18: INDONESIA | G18: WILD | H18: 30 | I18: VP | J18: Retail | K18: =VLOOKUP(C:C,Sheet2!B:H,7,0) -> 249
A19: LOLIGO ROLL 15/20cm (30) | B19: MUC ONG LOLIGO | C19: F0427 | D19: OOS | E19: 30 X 16 OZ | F19: INDONESIA | G19: WILD | H19: 30 | I19: VP | J19: Retail | K19: =VLOOKUP(C:C,Sheet2!B:H,7,0) -> #N/A
A20: LOLIGO ROLL 20/25cm (30) | B20: MUC ONG LOLIGO | C20: F0428 | D20: OOS | E20: 20 X 24 OZ | F20: INDONESIA | G20: WILD | H20: 30 | I20: VP | J20: Retail | K20: =VLOOKUP(C:C,Sheet2!B:H,7,0) -> #N/A
A21: LOLIGO SQUID T&T 3/5 (50) | B21: MUC NGUYEN CON | C21: F0410 | D21: 3.4 | E21: 20 X 2.5# | F21: CHINA | G21: WILD | H21: 50 | I21: VP | J21: Retail | K21: =VLOOKUP(C:C,Sheet2!B:H,7,0) -> 170
A22: LOLIGO SQUID TENTACLES (30) | B22: RAU MUC | C22: F0413 | D22: 3.7 | E22: 30 X 14 OZ | F22: CHINA | G22: WILD | H22: 26.25 | I22: VP | J22: Retail | K22: =VLOOKUP(C:C,Sheet2!B:H,7,0) -> 111
A23: LOLIGO SQUID TUBES 3/5 (50) | B23: THAN MUC ONG | C23: F0412 | D23: 3.7 | E23: 20 X 2.5# | F23: CHINA | G23: WILD | H23: 50 | I23: Box | J23: Retail | K23: =VLOOKUP(C:C,Sheet2!B:H,7,0) -> 185
A24: LOLIGO TENTACLES 10/20g (30) | B24: RAU MUC | C24: F0414 | D24: OOS | E24: 30 X 14 OZ | F24: INDONESIA | G24: WILD | H24: 26.25 | I24: VP | J24: Retail | K24: =VLOOKUP(C:C,Sheet2!B:H,7,0) -> 114
A25: LOLIGO TENTACLES 20/30g (30) | B25: RAU MUC | C25: F0415 | D25: 3.8 | E25: 30 X 14 OZ | F25: INDONESIA | G25: WILD | I25: VP | J25: Retail | K25: =VLOOKUP(C:C,Sheet2!B:H,7,0) -> 114
A26: LOLIGO TENTACLES 20/30g (30) | B26: RAU MUC | C26: F04141 | D26: OOS | E26: 30 X 14 OZ | F26: INDONESIA | G26: WILD | I26: VP | J26: Retail | K26: =VLOOKUP(C:C,Sheet2!B:H,7,0) -> #N/A
A27: LOLIGO TENTACLES 40/60g (30) | B27: RAU MUC | C27: F04143 | D27: 3.8 | E27: 30 X 14 OZ | F27: VIETNAM | G27: WILD | H27: 26.25 | I27: VP | J27: Retail | K27: =VLOOKUP(C:C,Sheet2!B:H,7,0) -> #N/A
A28: LOLIGO TENTACLES 60/80g (30) | B28: RAU MUC | C28: F04144 | D28: 3.8 | E28: 30 X 14 OZ | F28: VIETNAM | G28: WILD | H28: 26.25 | I28: VP | J28: Retail | K28: =VLOOKUP(C:C,Sheet2!B:H,7,0) -> #N/A
A29: OCTOPUS 1/2# (30) | B29: BACH TUOC LON | C29: F0270 | D29: 4.1 | E29: 1 X 30 LB | F29: INDONESIA | G29: WILD | H29: 30 | I29: IWP | J29: Bulk | K29: =VLOOKUP(C:C,Sheet2!B:H,7,0) -> 123
A30: OCTOPUS 2/4# (30) | B30: BACH TUOC LON | C30: F0271 | D30: 4.8 | E30: 1 X 30 LB | F30: INDONESIA | G30: WILD | H30: 30 | I30: IWP | J30: Bulk | K30: =VLOOKUP(C:C,Sheet2!B:H,7,0) -> 144
A31: OCTOPUS 4/6# (30) | B31: BACH TUOC LON | C31: F0272 | D31: 5.9 | E31: 1 X 30 LB | F31: INDONESIA | G31: WILD | H31: 30 | I31: IWP | J31: Bulk | K31: =VLOOKUP(C:C,Sheet2!B:H,7,0) -> 177
A32: OCTOPUS 6/8# (30) | B32: BACH TUOC LON | C32: F0273 | D32: 6.2 | E32: 1 X 30 LB | F32: INDONESIA | G32: WILD | H32: 30 | I32: IWP | J32: Bulk | K32: =VLOOKUP(C:C,Sheet2!B:H,7,0) -> 186
A33: SQUID TENTACLE SLICE (30) | B33: #N/A | C33: F0418 | D33: 4.2 | E33: 30 X 16 OZ | F33: PERU | G33: WILD | H33: 30 | I33: Bag | J33: Retail | K33: =VLOOKUP(C:C,Sheet2!B:H,7,0) -> 126
K34: =VLOOKUP(C:C,Sheet2!B:H,7,0) -> #N/A
A35: ▶ SHRIMP & PRAWNS | K35: =VLOOKUP(C:C,Sheet2!B:H,7,0) -> #N/A
A36: Product Description | B36: Vietnamese | C36: Item # | D36: Unit Price | E36: Packaging | F36: Origin | G36: Method | H36: Weight (lbs) | I36: Pack | J36: Pack Type | K36: =VLOOKUP(C:C,Sheet2!B:H,7,0) -> #N/A
A37: GIANT PRAWN BLC 2/4 (24) | B37: TOM CANG | C37: F0172 | D37: 10.9 | E37: 12 X 2 LB | F37: VIETNAM | G37: FARMED | H37: 24 | I37: Box | J37: Retail | K37: =VLOOKUP(C:C,Sheet2!B:H,7,0) -> 261.6
A38: GIANT PRAWN BLC 4/6 (24) | B38: TOM CANG | C38: F0173 | D38: 10.5 | E38: 12 X 2 LB | F38: VIETNAM | G38: FARMED | H38: 24 | I38: Box | J38: Retail | K38: =VLOOKUP(C:C,Sheet2!B:H,7,0) -> 252
A39: GIANT PRAWN BLC 6/8 (24) | B39: TOM CANG | C39: F0174 | D39: 8.5 | E39: 12 X 2 LB | F39: VIETNAM | G39: FARMED | H39: 24 | I39: Box | J39: Retail | K39: =VLOOKUP(C:C,Sheet2!B:H,7,0) -> 204
A40: GIANT PRAWN BLC 8/12 (24) | B40: TOM CANG | C40: F0175 | D40: 7.4 | E40: 12 X 2 LB | F40: VIETNAM | G40: FARMED | H40: 24 | I40: Box | J40: Retail | K40: =VLOOKUP(C:C,Sheet2!B:H,7,0) -> 177.6
A41: KRILL / BABY SHRIMPS (60x7oz) | B41: TEP BO | C41: F0701 | D41: 1.6 | E41: 60 X 7 OZ | F41: VIETNAM | G41: WILD | H41: 27 | I41: VP | J41: Retail | K41: =VLOOKUP(C:C,Sheet2!B:H,7,0) -> 96
...

Sheet Alphabetical Index
A1: ALPHABETICAL PRODUCT INDEX
A2: Quick lookup by product name
A4: Product Description | B4: Item # | C4: Origin | D4: Category | E4: Packaging | F4: Weight (lbs) | G4: Unit Price | H4: Case Price
A5: AMBERJACK (HAMACHI) 2-4# (44.1 | B5: F0332 | C5: KOREA | D5: FISH - TUNA & AMBERJACK | E5: 1 X 44.1# | F5: 44 | G5: 0 | H5: 0.8
A6: AROMA SPICY GREEN CHILI (60) | B6: F0370 | C6: VIETNAM | D6: OTHER | E6: 60 X 7 OZ | F6: 26.25 | G6: 0 | H6: 0
A7: BABY BONITA/BULLET TUNA (30) | B7: F0364 | C7: VIETNAM | D7: FISH - TUNA & AMBERJACK | E7: 15 X 2 LB | F7: 30 | G7: 0 | H7: 0
A8: BABY LOLIGO SQUID R/P (30) | B8: F0403 | C8: CHINA | D8: OCTOPUS & SQUID | E8: 30 X 14 OZ | F8: 26 | G8: 0 | H8: 0.5
A9: BABY MULLET W/R (20x1.5) | B9: F0320 | C9: VIETNAM | D9: FISH - SPECIALTY | E9: 20 X 1.5# | F9: 30 | G9: 0 | H9: 0
A10: BABY OCTOPUS DS 16/25 (24) | B10: F0296 | C10: VIETNAM | D10: OCTOPUS & SQUID | E10: 12 X 2 LB | F10: 24 | G10: 0 | H10: 0.4
A11: BABY OCTOPUS DS 5/15 (24) | B11: F0295 | C11: VIETNAM | D11: OCTOPUS & SQUID | E11: 12 X 2 LB | F11: 24 | G11: 0 | H11: 0
A12: BABY OCTOPUS SS 16/25 (12x2) | B12: F0291 | C12: VIETNAM | D12: OCTOPUS & SQUID | E12: 12 X 2 LB | F12: 24 | G12: 0 | H12: 0.4
A13: BABY OCTOPUS SS 5/15 (12x2) | B13: F0290 | C13: VIETNAM | D13: OCTOPUS & SQUID | E13: 12 X 2 LB | F13: 24 | G13: 0 | H13: 0
A14: BABY ROUNDSCAD (15x2) RND | B14: F0349 | C14: VIETNAM | D14: FISH - SPECIALTY | E14: 15 X 2 LB | F14: 30 | G14: 0 | H14: 0.5
A15: BANANA FISH (30) | B15: F0240 | C15: VIETNAM | D15: OTHER | E15: 30 X 14 OZ | F15: 26.4 | G15: 0 | H15: 0
A16: BELT FISH W/R 1000/1500 (22.05 | B16: F0464 | C16: VENESUELA | D16: OTHER | E16: 1 X 22.05# | F16: 22 | G16: 0 | H16: 0.79
... A272: YOUNG BLACK PEPPER (40) | B272: F0375 | C272: VIETNAM | D272: OTHER | E272: 40 X 4 OZ | F272: 10 | G272: 0 | H272: 0

Sheet Sheet1
A2: Run Date: 02/10/2026 | C2: SEAQUEST SEAFOOD | D2: CORPORATION | G2: Pag | H2: e: 1
A3: R/M Date: 02/10/2026 | C3: NEW PRICE | D3: LIST | G3: Tim | H3: e: 10:21 AM
A5: DESCRIPTION | B5: ITEM# | C5: ORIGIN | D5: MOC | E5: PACKAGING | F5: WEIGHT | G5: U. PRI | H5: CECASE PRICE
A7: SLT CROAKER 40/U (40) | B7: C0029 | C7: VIETNAM | D7: WILD | E7: 1 X 40 LB | F7: 40 | G7: 5.6 | H7: 224
A8: SLT KING MACK FILLET (40) | B8: C0031 | C8: VIETNAM | D8: WILD | E8: 1 X 40 LB | F8: 40 | G8: 8.7 | H8: 348
A9: SLT SABA MACK FILET (22) | B9: C0037 | C9: TAIWAN | D9: WILD | E9: 22 X 6.4 Z | F9: 8.8 | G9: 1.9 | H9: 41.8
A10: DH KRILL (20) | B10: C0041 | C10: VIETNAM | D10: WILD | E10: 20 X 8 OZ | F10: 10 | G10: 3.8 | H10: 76
A11: DH KRILL (10) | B11: C0044 | C11: VIETNAM | D11: WILD | E11: 1 X 10 LB | F11: 10 | G11: 7.5 | H11: 75
A12: DH BABY SQUID SKIN-ON (20x8) | B12: C0053 | C12: VIETNAM | D12: WILD | E12: 20 X 8 OZ | F12: 10 | G12: 6.4 | H12: 128
A13: DH MUDFISH STRIPS (33) | B13: C0065 | C13: VIETNAM | D13: FARMED | E13: 1 X 33 LB | F13: 33 | G13: 5 | H13: 165
A14: SLT CONGER EEL FILET (30) | B14: C0072 | C14: VIETNAM | D14: FARMED | E14: 30 X 12 OZ | F14: 22.5 | G14: 5.4 | H14: 162
A15: DH SEASONED RIVERBARB (60) | B15: C0140 | C15: VIETNAM | D15: FARMED | E15: 60 X 10 OZ | F15: 37.5 | G15: 3.5 | H15: 210
A16: DRIED KRILL/SHRIMP MED (80) | B16: C0152 | C16: VIETNAM | D16: WILD | E16: 80 X 3 OZ | F16: 15 | G16: 1.8 | H16: 144
A17: DRIED KRILL/SHRIMP LRG (80) | B17: C0153 | C17: VIETNAM | D17: WILD | E17: 80 X 3 OZ | F17: 15 | G17: 2 | H17: 160
A18: DH FILE FISH (22) | B18: C0170 | C18: VIETNAM | D18: WILD | E18: 1 X 22 LB | F18: 22 | G18: 6.8 | H18: 149.6
... A52: ROHU 800/1200 (40) | B52: F0127 | C52: THAILAND | D52: FARMED | E52: 1 X 40 LB | F52: 40 | G52: 2.6 | H52: 104
A57: 1) OCTOPUS
A58: 2) CUTTLEFISH
A59: 3) CRAB MEAT
A60: 4) CLAM
A61: 5) CONCH MEAT
A62: 6) FROG LEG
A63: 7) POMFRET
A64: 8) SCHRIMP
A65: 9) SQUID
A66: 10) SWAI
A67: 11) TILAPIA
A68: 12) AGRICULTURAL ITEMS
... A73: 21) FISH PASTE
A89: ROHU1200/1500 (40) | B89: F0128 | C89: THAILAND | D89: FARMED | E89: 1 X 40 LB | F89: 40 | G89: 2.6 | H89: 104
A90: STM GUTTED MACKEREL 2P (30) | B90: F0141 | C90: VIETNAM | D90: WILD | E90: 30 X 8 OZ | F90: 15 | G90: 2.65 | H90: 79.5
A91: STM GUTTED MACKEREL 3P (30) | B91: F0142 | C91: VIETNAM | D91: WILD | E91: 30 X 8 OZ | F91: 15 | G91: 2.65 | H91: 79.5
A92: YLW STRIPE TREVALLY (30x14) | B92: F0151 | C92: VIETNAM | D92: WILD | E92: 30 X 14 OZ | F92: 27 | G92: 2.1 | H92: 63
A93: SILVERBARB 300/500 (30) | B93: F0154 | C93: VIETNAM | D93: FARMED | E93: 15 X 2 LBS | F93: 30 | G93: 3.5 | H93: 105
A94: SILVERBARB 500/800 | B94: F0155 | C94: VIETNAM | D94: FARMED | E94: 1 X 33 LB | F94: 33 | G94: 3.6 | H94: 118.8
A95: RIVERBARB 250/300 R/P (30) | B95: F0162 | C95: VIETNAM | D95: FARMED | E95: 15 X 2 LB | F95: 30 | G95: 3.9 | H95: 117
A96: OLIVE BARB 800/1000 | B96: F0169 | C96: MYANMAR | D96: WILD | E96: 1 X 33 LB | F96: 33 | G96: 3.3 | H96: 108.9
A154: Run Date: 02/10/2026 | C154: SEAQUEST SEAFOOD | D154: CORPORATION | G154: Pag | H154: e: 2
A155: R/M Date: 02/10/2026 | C155: NEW PRICE | D155: LIST | G155: Tim | H155: e: 10:21 AM
A157: DESCRIPTION | B157: ITEM# | C157: ORIGIN | D157: MOC | E157: PACKAGING | F157: WEIGHT | G157: U. PRI | H157: CECASE PRICE
...

Sheet Sheet2
A2: Run Date: 03/02/2026 | C2: SEAQUEST SEAFOOD | D2: CORPORATION | G2: Pag | H2: e: 1
A3: R/M Date: 03/02/2026 | C3: NEW PRICE | D3: LIST | G3: Tim | H3: e: 10:08 AM
A5: DESCRIPTION | B5: ITEM# | C5: ORIGIN | D5: MOC | E5: PACKAGING | F5: WEIGHT | G5: U. PRI | H5: CECASE PRICE
A7: SLT CROAKER 40/U (40) | B7: C0029 | C7: VIETNAM | D7: WILD | E7: 1 X 40 LB | F7: 40 | G7: 5.6 | H7: 224
A8: SLT KING MACK FILLET (40) | B8: C0031 | C8: VIETNAM | D8: WILD | E8: 1 X 40 LB | F8: 40 | G8: 8.7 | H8: 348
A9: SLT SABA MACK FILET (22) | B9: C0037 | C9: TAIWAN | D9: WILD | E9: 22 X 6.4 Z | F9: 8.8 | G9: 1.9 | H9: 41.8
A10: DH KRILL (20) | B10: C0041 | C10: VIETNAM | D10: WILD | E10: 20 X 8 OZ | F10: 10 | G10: 3.8 | H10: 76
A11: DH KRILL (10) | B11: C0044 | C11: VIETNAM | D11: WILD | E11: 1 X 10 LB | F11: 10 | G11: 7.5 | H11: 75
A12: DH BABY SQUID SKIN-ON (20x8) | B12: C0053 | C12: VIETNAM | D12: WILD | E12: 20 X 8 OZ | F12: 10 | G12: 6.4 | H12: 128
A13: DH MUDFISH STRIPS (33) | B13: C0065 | C13: VIETNAM | D13: FARMED | E13: 1 X 33 LB | F13: 33 | G13: 5 | H13: 165
A14: SLT CONGER EEL FILET (30) | B14: C0072 | C14: VIETNAM | D14: FARMED | E14: 30 X 12 OZ | F14: 22.5 | G14: 5.4 | H14: 162
A15: DH SEASONED RIVERBARB (60) | B15: C0140 | C15: VIETNAM | D15: FARMED | E15: 60 X 10 OZ | F15: 37.5 | G15: 3.5 | H15: 210
A16: DRIED KRILL/SHRIMP MED (80) | B16: C0152 | C16: VIETNAM | D16: WILD | E16: 80 X 3 OZ | F16: 15 | G16: 1.8 | H16: 144
A17: DRIED KRILL/SHRIMP LRG (80) | B17: C0153 | C17: VIETNAM | D17: WILD | E17: 80 X 3 OZ | F17: 15 | G17: 2 | H17: 160
A18: DH ANCHOVY 2/3 (22) | B18: C0161 | C18: VIETNAM | D18: WILD | E18: 1 X 22 LB | F18: 22 | G18: 4 | H18: 88
... A74: OLIVE BARB 500/800 | B74: F0168 | C74: MYANMAR | D74: WILD | E74: 1 X 33 LB | F74: 33 | G74: 3.4 | H74: 112.2
A132: Run Date: 03/02/2026 | C132: SEAQUEST SEAFOOD | D132: CORPORATION | G132: Pag | H132: e: 2
A133: R/M Date: 03/02/2026 | C133: NEW PRICE | D133: LIST | G133: Tim | H133: e: 10:08 AM
A135: DESCRIPTION | B135: ITEM# | C135: ORIGIN | D135: MOC | E135: PACKAGING | F135: WEIGHT | G135: U. PRI | H135: CECASE PRICE
A137: OLIVE BARB 800/1000 | B137: F0169 | C137: MYANMAR | D137: WILD | E137: 1 X 33 LB | F137: 33 | G137: 3.3 | H137: 108.9
A138: GIANT PRAWN BLC 2/4 (24) | B138: F0172 | C138: VIETNAM | D138: FARMED | E138: 12 X 2 LB | F138: 24 | G138: 10.9 | H138: 261.6
A139: GIANT PRAWN BLC 4/6 (24) | B139: F0173 | C139: VIETNAM | D139: FARMED | E139: 12 X 2 LB | F139: 24 | G139: 10.5 | H139: 252
A140: GIANT PRAWN BLC 6/8 (24) | B140: F0174 | C140: VIETNAM | D140: FARMED | E140: 12 X 2 LB | F140: 24 | G140: 8.5 | H140: 204
A141: GIANT PRAWN BLC 8/12 (24) | B141: F0175 | C141: VIETNAM | D141: FARMED | E141: 12 X 2 LBS | F141: 24 | G141: 7.4 | H141: 177.6
A142: RIVER CARP H&G (30) | B142: F0191 | C142: VIETNAM | D142: WILD | E142: 30 X 14 OZ | F142: 26.5 | G142: 2.8 | H142: 84
A143: CLIMBING PERCH CLN (30) | B143: F0205 | C143: VIETNAM | D143: FARMED | E143: 30 X 14 OZ | F143: 26.25 | G143: 2.95 | H143: 88.5
A144: GOURAMI FISH CLN (30) | B144: F0210 | C144: VIETNAM | D144: WILD | E144: 30 X 14 OZ | F144: 26.25 | G144: 4.2 | H144: 126
A145: HILSA FISH 400/600 (30) | B145: F0220 | C145: MYANMAR | D145: WILD | E145: 15 X 2 LB | F145: 30 | G145: 7.7 | H145: 231
A146: HILSA FISH 500/800 | B146: F0221 | C146: MYANMAR | D146: WILD | E146: 1 X 33 LB | F146: 33 | G146: 8 | H146: 264
A147: HILSA FISH 1000/1200g | B147: F0223 | C147: MYANMAR | D147: WILD | E147: 1 X 33 LB | F147: 33 | G147: 9.8 | H147: 323.4
A148: HILSA FISH 1200/1500g | B148: F0224 | C148: MYANMAR | D148: WILD | E148: 1 X 33 LB | F148: 33 | G148: 10.5 | H148: 346.5
... A204: PALM NUT S 18/24 (40) | B204: F0378 | C204: VIETNAM | D204: WILD | E204: 40 X 16 OZ | F204: 40 | G204: 3.5 | H204: 140
A262: Run Date: 03/02/2026 | C262: SEAQUEST SEAFOOD | D262: CORPORATION | G262: Pag | H262: e: 3
A263: R/M Date: 03/02/2026 | C263: NEW PRICE | D263: LIST | G263: Tim | H263: e: 10:08 AM
A265: DESCRIPTION | B265: ITEM# | C265: ORIGIN | D265: MOC | E265: PACKAGING | F265: WEIGHT | G265: U. PRI | H265: CECASE PRICE
A267: PALM NUT M 16/18 (40) | B267: F0379 | C267: VIETNAM | D267: WILD | E267: 40 X 16 OZ | F267: 40 | G267: 3.5 | H267: 140
A268: SILVER / ICE FISH 3/5 (44) | B268: F0380 | C268: CHINA | D268: WILD | E268: 20 X 2.2# | F268: 44 | G268: 4.65 | H268: 204.6
A269: SILVER / ICE FISH 3/5 (60x8) | B269: F0384 | C269: CHINA | D269: WILD | E269: 60 X 8 OZ | F269: 30 | G269: 3.4 | H269: 204
A270: GRAY/SILVER ANCHOVY 5/7 (30) | B270: F0390 | C270: VIETNAM | D270: WILD | E270: 30 X 14 OZ | F270: 26.25 | G270: 2.8 | H270: 84
A271: WHT ANCHOVY H/L (30) | B271: F0393 | C271: VIETNAM | D271: WILD | E271: 30 X 14 OZ | F271: 26.25 | G271: 2.8 | H271: 84
...
